Workbook
Name Slicer_Month: #N/A
Name Slicer_Region: #N/A

Sheet Input Data
A1: DATE | B1: CUSTOMER NAME | C1: PRODUCT | D1: UNIT PRICE ($) | E1: QUANTITY | F1: Actual | G1: Country | H1: Region | I1: Month | J1: Week
A2: 44197 | B2: Customer33 | C2: Product24 | D2: 156.96 | E2: 9 | F2: =InputData[[#This Row],[UNIT PRICE ($)]]*InputData[[#This Row],[QUANTITY]] -> 1412.64 | G2: =VLOOKUP(InputData[[#This Row],[CUSTOMER NAME]],Country[],2,0) -> India | H2: =VLOOKUP(InputData[[#This Row],[CUSTOMER NAME]],Country[],3,0) -> Western | I2: =TEXT(InputData[[#This Row],[DATE]],"mmm") -> Jan | J2: =WEEKNUM(InputData[[#This Row],[DATE]]) -> 1
A3: 44197 | B3: Customer29 | C3: Product22 | D3: 141.57 | E3: 1 | F3: =InputData[[#This Row],[UNIT PRICE ($)]]*InputData[[#This Row],[QUANTITY]] -> 141.57 | G3: =VLOOKUP(InputData[[#This Row],[CUSTOMER NAME]],Country[],2,0) -> India | H3: =VLOOKUP(InputData[[#This Row],[CUSTOMER NAME]],Country[],3,0) -> South | I3: =TEXT(InputData[[#This Row],[DATE]],"mmm") -> Jan | J3: =WEEKNUM(InputData[[#This Row],[DATE]]) -> 1
A4: 44198 | B4: Customer31 | C4: Product38 | D4: 79.92 | E4: 15 | F4: =InputData[[#This Row],[UNIT PRICE ($)]]*InputData[[#This Row],[QUANTITY]] -> 1198.8 | G4: =VLOOKUP(InputData[[#This Row],[CUSTOMER NAME]],Country[],2,0) -> India | H4: =VLOOKUP(InputData[[#This Row],[CUSTOMER NAME]],Country[],3,0) -> North | I4: =TEXT(InputData[[#This Row],[DATE]],"mmm") -> Jan | J4: =WEEKNUM(InputData[[#This Row],[DATE]]) -> 1
A5: 44198 | B5: Customer03 | C5: Product33 | D5: 119.7 | E5: 1 | F5: =InputData[[#This Row],[UNIT PRICE ($)]]*InputData[[#This Row],[QUANTITY]] -> 119.7 | G5: =VLOOKUP(InputData[[#This Row],[CUSTOMER NAME]],Country[],2,0) -> India | H5: =VLOOKUP(InputData[[#This Row],[CUSTOMER NAME]],Country[],3,0) -> Northeast | I5: =TEXT(InputData[[#This Row],[DATE]],"mmm") -> Jan | J5: =WEEKNUM(InputData[[#This Row],[DATE]]) -> 1
A6: 44198 | B6: Customer05 | C6: Product15 | D6: 15.72 | E6: 2 | F6: =InputData[[#This Row],[UNIT PRICE ($)]]*InputData[[#This Row],[QUANTITY]] -> 31.44 | G6: =VLOOKUP(InputData[[#This Row],[CUSTOMER NAME]],Country[],2,0) -> India | H6: =VLOOKUP(InputData[[#This Row],[CUSTOMER NAME]],Country[],3,0) -> Northeast | I6: =TEXT(InputData[[#This Row],[DATE]],"mmm") -> Jan | J6: =WEEKNUM(InputData[[#This Row],[DATE]]) -> 1
A7: 44198 | B7: Customer35 | C7: Product10 | D7: 164.28 | E7: 7 | F7: =InputData[[#This Row],[UNIT PRICE ($)]]*InputData[[#This Row],[QUANTITY]] -> 1149.96 | G7: =VLOOKUP(InputData[[#This Row],[CUSTOMER NAME]],Country[],2,0) -> India | H7: =VLOOKUP(InputData[[#This Row],[CUSTOMER NAME]],Country[],3,0) -> North | I7: =TEXT(InputData[[#This Row],[DATE]],"mmm") -> Jan | J7: =WEEKNUM(InputData[[#This Row],[DATE]]) -> 1
A8: 44198 | B8: Customer38 | C8: Product13 | D8: 122.08 | E8: 6 | F8: =InputData[[#This Row],[UNIT PRICE ($)]]*InputData[[#This Row],[QUANTITY]] -> 732.48 | G8: =VLOOKUP(InputData[[#This Row],[CUSTOMER NAME]],Country[],2,0) -> India | H8: =VLOOKUP(InputData[[#This Row],[CUSTOMER NAME]],Country[],3,0) -> Northeast | I8: =TEXT(InputData[[#This Row],[DATE]],"mmm") -> Jan | J8: =WEEKNUM(InputData[[#This Row],[DATE]]) -> 1
A9: 44198 | B9: Customer39 | C9: Product15 | D9: 15.72 | E9: 25 | F9: =InputData[[#This Row],[UNIT PRICE ($)]]*InputData[[#This Row],[QUANTITY]] -> 393 | G9: =VLOOKUP(InputData[[#This Row],[CUSTOMER NAME]],Country[],2,0) -> Germany | H9: =VLOOKUP(InputData[[#This Row],[CUSTOMER NAME]],Country[],3,0) -> Export | I9: =TEXT(InputData[[#This Row],[DATE]],"mmm") -> Jan | J9: =WEEKNUM(InputData[[#This Row],[DATE]]) -> 1
A10: 44199 | B10: Customer34 | C10: Product14 | D10: 146.72 | E10: 21 | F10: =InputData[[#This Row],[UNIT PRICE ($)]]*InputData[[#This Row],[QUANTITY]] -> 3081.12 | G10: =VLOOKUP(InputData[[#This Row],[CUSTOMER NAME]],Country[],2,0) -> India | H10: =VLOOKUP(InputData[[#This Row],[CUSTOMER NAME]],Country[],3,0) -> Northeast | I10: =TEXT(InputData[[#This Row],[DATE]],"mmm") -> Jan | J10: =WEEKNUM(InputData[[#This Row],[DATE]]) -> 2
A11: 44199 | B11: Customer18 | C11: Product43 | D11: 83.08 | E11: 9 | F11: =InputData[[#This Row],[UNIT PRICE ($)]]*InputData[[#This Row],[QUANTITY]] -> 747.72 | G11: =VLOOKUP(InputData[[#This Row],[CUSTOMER NAME]],Country[],2,0) -> India | H11: =VLOOKUP(InputData[[#This Row],[CUSTOMER NAME]],Country[],3,0) -> Western | I11: =TEXT(InputData[[#This Row],[DATE]],"mmm") -> Jan | J11: =WEEKNUM(InputData[[#This Row],[DATE]]) -> 2
A12: 44199 | B12: Customer20 | C12: Product38 | D12: 79.92 | E12: 31 | F12: =InputData[[#This Row],[UNIT PRICE ($)]]*InputData[[#This Row],[QUANTITY]] -> 2477.52 | G12: =VLOOKUP(InputData[[#This Row],[CUSTOMER NAME]],Country[],2,0) -> United Kingdom | H12: =VLOOKUP(InputData[[#This Row],[CUSTOMER NAME]],Country[],3,0) -> Export | I12: =TEXT(InputData[[#This Row],[DATE]],"mmm") -> Jan | J12: =WEEKNUM(InputData[[#This Row],[DATE]]) -> 2
A13: 44199 | B13: Customer37 | C13: Product04 | D13: 48.84 | E13: 5 | F13: =InputData[[#This Row],[UNIT PRICE ($)]]*InputData[[#This Row],[QUANTITY]] -> 244.2 | G13: =VLOOKUP(InputData[[#This Row],[CUSTOMER NAME]],Country[],2,0) -> United States of America | H13: =VLOOKUP(InputData[[#This Row],[CUSTOMER NAME]],Country[],3,0) -> Export | I13: =TEXT(InputData[[#This Row],[DATE]],"mmm") -> Jan | J13: =WEEKNUM(InputData[[#This Row],[DATE]]) -> 2
... A833: 44561 | B833: Customer18 | C833: Product33 | D833: 119.7 | E833: 12 | F833: =InputData[[#This Row],[UNIT PRICE ($)]]*InputData[[#This Row],[QUANTITY]] -> 1436.4 | G833: =VLOOKUP(InputData[[#This Row],[CUSTOMER NAME]],Country[],2,0) -> India | H833: =VLOOKUP(InputData[[#This Row],[CUSTOMER NAME]],Country[],3,0) -> Western | I833: =TEXT(InputData[[#This Row],[DATE]],"mmm") -> Dec | J833: =WEEKNUM(InputData[[#This Row],[DATE]]) -> 53

Sheet Pivot Table
A1: Sum of Actual | C1: Country | D1: Sum of Actual | F1: Region | G1: Sum of Actual | I1: Month | J1: Sum of Actual | L1: CUSTOMER NAME | M1: Sum of Actual | O1: PRODUCT | P1: Sum of Actual | S1: Week | T1: Sum of Actual
A2: 984571.06 | C2: Bangladesh | D2: 31336.23 | F2: Central | G2: 72920.48 | I2: Jan | J2: 92118.79 | L2: Customer33 | M2: 60929.15 | O2: Product30 | P2: 57968.64 | S2: 1 | T2: 5179.59
C3: Brazil | D3: 39438.44 | F3: East | G3: 75939.73 | I3: Feb | J3: 91137.05 | L3: Customer22 | M3: 45112.95 | O3: Product41 | P3: 57554.28 | S3: 2 | T3: 21116.73
A4: =GETPIVOTDATA("Actual",$A$1) -> 984571.06 | C4: Ethiopia | D4: 39653.93 | F4: Export | G4: 531575.62 | I4: Mar | J4: 97920.72 | L4: Customer23 | M4: 43062.83 | O4: Product24 | P4: 49599.36 | S4: 3 | T4: 14261.19
C5: France | D5: 14337.4 | F5: North | G5: 45081.78 | I5: Apr | J5: 72320.89 | O5: Product19 | P5: 41580 | S5: 4 | T5: 11433.2
C6: Germany | D6: 16810.72 | F6: Northeast | G6: 83994.49 | I6: May | J6: 70511.76 | O6: Product22 | P6: 41055.3 | S6: 5 | T6: 33727.55
C7: India | D7: 452995.44 | F7: South | G7: 53277.57 | I7: Jun | J7: 66727.4 | O7: Product32 | P7: 40883.04 | S7: 6 | T7: 34794.82
C8: Indonesia | D8: 8394.32 | F8: Western | G8: 121781.39 | I8: Jul | J8: 92661.55 | O8: Product21 | P8: 39659.76 | S8: 7 | T8: 32107.1
C9: Mexico | D9: 65776.76 | I9: Aug | J9: 69125.75 | L9: =L2 -> Customer33 | M9: =M2 -> 60929.15 | O9: Product05 | P9: 38591.28 | S9: 8 | T9: 11777.67
C10: Nigeria | D10: 39993.27 | I10: Sep | J10: 78253.53 | L10: =L3 -> Customer22 | M10: =M3 -> 45112.95 | O10: Product42 | P10: 38232 | S10: 9 | T10: 17571.59
C11: Pakistan | D11: 77523.28 | I11: Oct | J11: 87136.37 | L11: =L4 -> Customer23 | M11: =M4 -> 43062.83 | O11: Product10 | P11: 34991.64 | S11: 10 | T11: 17413.3
C12: Russia | D12: 63344.34 | I12: Nov | J12: 75659.86 | S12: 11 | T12: 18811.39
C13: Saudi Arabia | D13: 38317.79 | I13: Dec | J13: 90997.39 | S13: 12 | T13: 29446.46
C14: South Africa | D14: 32808.02 | S14: 13 | T14: 22723.6
C15: United Kingdom | D15: 50749.04 | S15: 14 | T15: 13729.81
C16: United States of America | D16: 13092.08 | S16: 15 | T16: 27820.09
S17: 16 | T17: 9407.51
S18: 17 | T18: 22127.3
S19: 18 | T19: 11809.4
C20: =C2 -> Bangladesh | D20: =D2 -> 31336.23 | S20: 19 | T20: 12750.54
C21: =C3 -> Brazil | D21: =D3 -> 39438.44 | S21: 20 | T21: 19691.76
C22: =C4 -> Ethiopia | D22: =D4 -> 39653.93 | S22: 21 | T22: 19171.71
C23: =C5 -> France | D23: =D5 -> 14337.4 | S23: 22 | T23: 11617.86
C24: =C6 -> Germany | D24: =D6 -> 16810.72 | S24: 23 | T24: 17000.62
C25: =C7 -> India | D25: =D7 -> 452995.44 | S25: 24 | T25: 15273.35
C26: =C8 -> Indonesia | D26: =D8 -> 8394.32 | S26: 25 | T26: 23043.47
C27: =C9 -> Mexico | D27: =D9 -> 65776.76 | S27: 26 | T27: 13593.79
C28: =C10 -> Nigeria | D28: =D10 -> 39993.27 | S28: 27 | T28: 13197.89
C29: =C11 -> Pakistan | D29: =D11 -> 77523.28 | S29: 28 | T29: 13311.34
C30: =C12 -> Russia | D30: =D12 -> 63344.34 | S30: 29 | T30: 26662.81
C31: =C13 -> Saudi Arabia | D31: =D13 -> 38317.79 | S31: 30 | T31: 15652.32
... C34: =C16 -> United States of America | D34: =D16 -> 13092.08 | S34: 33 | T34: 17406.18
S35: 34 | T35: 10403.35
S36: 35 | T36: 29524.29
S37: 36 | T37: 14336.82
S38: 37 | T38: 15584.3
S39: 38 | T39: 13437.32
S40: 39 | T40: 30057.11
S41: 40 | T41: 17799.13
S42: 41 | T42: 25449.57
...

Sheet Dashboard

Sheet Target
A1: Month | B1: Month Name | C1: Target ($) | D1: Actual | E1: Below | F1: Above
A2: 1 | B2: Jan | C2: 90000 | D2: =VLOOKUP(TargetData[[#This Row],[Month Name]],'Pivot Table'!I1:J13,2,0) -> 92118.79 | E2: =IF(TargetData[[#This Row],[Actual]]<TargetData[[#This Row],[Target ($)]],TargetData[[#This Row],[Actual]],NA()) -> #N/A | F2: =IF(TargetData[[#This Row],[Actual]]>=TargetData[[#This Row],[Target ($)]],TargetData[[#This Row],[Actual]],NA()) -> 92118.79
A3: 2 | B3: Feb | C3: 100000 | D3: =VLOOKUP(TargetData[[#This Row],[Month Name]],'Pivot Table'!I2:J14,2,0) -> 91137.05 | E3: =IF(TargetData[[#This Row],[Actual]]<TargetData[[#This Row],[Target ($)]],TargetData[[#This Row],[Actual]],NA()) -> 91137.05 | F3: =IF(TargetData[[#This Row],[Actual]]>=TargetData[[#This Row],[Target ($)]],TargetData[[#This Row],[Actual]],NA()) -> #N/A
A4: 3 | B4: Mar | C4: 100000 | D4: =VLOOKUP(TargetData[[#This Row],[Month Name]],'Pivot Table'!I3:J15,2,0) -> 97920.72 | E4: =IF(TargetData[[#This Row],[Actual]]<TargetData[[#This Row],[Target ($)]],TargetData[[#This Row],[Actual]],NA()) -> 97920.72 | F4: =IF(TargetData[[#This Row],[Actual]]>=TargetData[[#This Row],[Target ($)]],TargetData[[#This Row],[Actual]],NA()) -> #N/A
A5: 4 | B5: Apr | C5: 100000 | D5: =VLOOKUP(TargetData[[#This Row],[Month Name]],'Pivot Table'!I4:J16,2,0) -> 72320.89 | E5: =IF(TargetData[[#This Row],[Actual]]<TargetData[[#This Row],[Target ($)]],TargetData[[#This Row],[Actual]],NA()) -> 72320.89 | F5: =IF(TargetData[[#This Row],[Actual]]>=TargetData[[#This Row],[Target ($)]],TargetData[[#This Row],[Actual]],NA()) -> #N/A
A6: 5 | B6: May | C6: 90000 | D6: =VLOOKUP(TargetData[[#This Row],[Month Name]],'Pivot Table'!I5:J17,2,0) -> 70511.76 | E6: =IF(TargetData[[#This Row],[Actual]]<TargetData[[#This Row],[Target ($)]],TargetData[[#This Row],[Actual]],NA()) -> 70511.76 | F6: =IF(TargetData[[#This Row],[Actual]]>=TargetData[[#This Row],[Target ($)]],TargetData[[#This Row],[Actual]],NA()) -> #N/A
A7: 6 | B7: Jun | C7: 90000 | D7: =VLOOKUP(TargetData[[#This Row],[Month Name]],'Pivot Table'!I6:J18,2,0) -> 66727.4 | E7: =IF(TargetData[[#This Row],[Actual]]<TargetData[[#This Row],[Target ($)]],TargetData[[#This Row],[Actual]],NA()) -> 66727.4 | F7: =IF(TargetData[[#This Row],[Actual]]>=TargetData[[#This Row],[Target ($)]],TargetData[[#This Row],[Actual]],NA()) -> #N/A
A8: 7 | B8: Jul | C8: 90000 | D8: =VLOOKUP(TargetData[[#This Row],[Month Name]],'Pivot Table'!I7:J19,2,0) -> 92661.55 | E8: =IF(TargetData[[#This Row],[Actual]]<TargetData[[#This Row],[Target ($)]],TargetData[[#This Row],[Actual]],NA()) -> #N/A | F8: =IF(TargetData[[#This Row],[Actual]]>=TargetData[[#This Row],[Target ($)]],TargetData[[#This Row],[Actual]],NA()) -> 92661.55
A9: 8 | B9: Aug | C9: 90000 | D9: =VLOOKUP(TargetData[[#This Row],[Month Name]],'Pivot Table'!I8:J20,2,0) -> 69125.75 | E9: =IF(TargetData[[#This Row],[Actual]]<TargetData[[#This Row],[Target ($)]],TargetData[[#This Row],[Actual]],NA()) -> 69125.75 | F9: =IF(TargetData[[#This Row],[Actual]]>=TargetData[[#This Row],[Target ($)]],TargetData[[#This Row],[Actual]],NA()) -> #N/A
A10: 9 | B10: Sep | C10: 90000 | D10: =VLOOKUP(TargetData[[#This Row],[Month Name]],'Pivot Table'!I9:J21,2,0) -> 78253.53 | E10: =IF(TargetData[[#This Row],[Actual]]<TargetData[[#This Row],[Target ($)]],TargetData[[#This Row],[Actual]],NA()) -> 78253.53 | F10: =IF(TargetData[[#This Row],[Actual]]>=TargetData[[#This Row],[Target ($)]],TargetData[[#This Row],[Actual]],NA()) -> #N/A
A11: 10 | B11: Oct | C11: 80000 | D11: =VLOOKUP(TargetData[[#This Row],[Month Name]],'Pivot Table'!I10:J22,2,0) -> 87136.37 | E11: =IF(TargetData[[#This Row],[Actual]]<TargetData[[#This Row],[Target ($)]],TargetData[[#This Row],[Actual]],NA()) -> #N/A | F11: =IF(TargetData[[#This Row],[Actual]]>=TargetData[[#This Row],[Target ($)]],TargetData[[#This Row],[Actual]],NA()) -> 87136.37
A12: 11 | B12: Nov | C12: 80000 | D12: =VLOOKUP(TargetData[[#This Row],[Month Name]],'Pivot Table'!I11:J23,2,0) -> 75659.86 | E12: =IF(TargetData[[#This Row],[Actual]]<TargetData[[#This Row],[Target ($)]],TargetData[[#This Row],[Actual]],NA()) -> 75659.86 | F12: =IF(TargetData[[#This Row],[Actual]]>=TargetData[[#This Row],[Target ($)]],TargetData[[#This Row],[Actual]],NA()) -> #N/A
A13: 12 | B13: Dec | C13: 80000 | D13: =VLOOKUP(TargetData[[#This Row],[Month Name]],'Pivot Table'!I12:J24,2,0) -> 90997.39 | E13: =IF(TargetData[[#This Row],[Actual]]<TargetData[[#This Row],[Target ($)]],TargetData[[#This Row],[Actual]],NA()) -> #N/A | F13: =IF(TargetData[[#This Row],[Actual]]>=TargetData[[#This Row],[Target ($)]],TargetData[[#This Row],[Actual]],NA()) -> 90997.39

Sheet Customer
A1: Customer Name | B1: Country | C1: Region
A2: Customer01 | B2: Nigeria | C2: Export
A3: Customer02 | B3: Bangladesh | C3: Export
A4: Customer03 | B4: India | C4: Northeast
A5: Customer04 | B5: Saudi Arabia | C5: Export
A6: Customer05 | B6: India | C6: Northeast
A7: Customer06 | B7: Pakistan | C7: Export
A8: Customer07 | B8: Indonesia | C8: Export
A9: Customer08 | B9: United Kingdom | C9: Export
A10: Customer09 | B10: Russia | C10: Export
A11: Customer10 | B11: India | C11: South
A12: Customer11 | B12: Mexico | C12: Export
... A41: Customer40 | B41: United States of America | C41: Export
